<?xml version="1.0" ?>
<!-- =================================================================================== -->
<!-- |    This document was autogenerated by xacro from panda_four.urdf.xacro          | -->
<!-- |    EDITING THIS FILE BY HAND IS NOT RECOMMENDED                                 | -->
<!-- =================================================================================== -->
<robot name="panda">
  <!-- box shaped table as base for the 4 Pandas -->
  <link name="base">
    <visual>
      <origin rpy="0 0 0" xyz="0 0 0.05"/>
      <geometry>
        <box size="2 2 0.1"/>
      </geometry>
      <material name="Pastel Gray">
        <color rgba="0.7 0.7 0.7 0.2"/>
      </material>
    </visual>
    <collision>
      <origin rpy="0 0 0" xyz="0 0 0.05"/>
      <geometry>
        <box size="2 2 0.1"/>
      </geometry>
    </collision>
  </link>
  <joint name="base_link_to_crate0_joint" type="fixed">
    <parent link="base"/>
    <child link="crate0"/>
    <origin rpy="0 0 1.57" xyz="0.53 0.1 0.1"/>
  </joint>
  <link name="crate0">
    <visual>
      <origin rpy="0 0 0" xyz="0.0 0.0 0.0"/>
      <geometry>
        <mesh filename="package://mramp/stl/crate.stl" scale="0.01 0.01 0.01"/>
      </geometry>
    </visual>
    <!-- <collision>
      <origin rpy="0 0 0" xyz="0.0 0.0 0.0"/>
      <geometry>
        <mesh filename="package://mramp/stl/crate.stl" scale="0.01 0.01 0.01"/>
      </geometry>
    </collision> -->
  </link>
  <joint name="base_link_to_crate_joint" type="fixed">
    <parent link="base"/>
    <child link="crate"/>
    <origin rpy="0 0 1.57" xyz="0.13 0.1 0.1"/>
  </joint>
  <link name="crate">
    <visual>
      <origin rpy="0 0 0" xyz="0.0 0.0 0.0"/>
      <geometry>
        <mesh filename="package://mramp/stl/crate.stl" scale="0.01 0.01 0.01"/>
      </geometry>
    </visual>
    <!-- <collision>
      <origin rpy="0 0 0" xyz="0.0 0.0 0.0"/>
      <geometry>
        <mesh filename="package://mramp/stl/crate.stl" scale="0.01 0.01 0.01"/>
      </geometry>
    </collision> -->
  </link>
  <joint name="base_link_to_crate1_joint" type="fixed">
    <parent link="base"/>
    <child link="crate1"/>
    <origin rpy="0 0 1.57" xyz="-0.27 0.1 0.1"/>
  </joint>
  <link name="crate1">
    <visual>
      <origin rpy="0 0 0" xyz="0.0 0.0 0.0"/>
      <geometry>
        <mesh filename="package://mramp/stl/crate.stl" scale="0.01 0.01 0.01"/>
      </geometry>
    </visual>
    <!-- <collision>
      <origin rpy="0 0 0" xyz="0.0 0.0 0.0"/>
      <geometry>
        <mesh filename="package://mramp/stl/crate.stl" scale="0.01 0.01 0.01"/>
      </geometry>
    </collision> -->
  </link>
  <joint name="base_link_to_crate2_joint" type="fixed">
    <parent link="base"/>
    <child link="crate2"/>
    <origin rpy="0 0 1.57" xyz="-0.67 0.1 0.1"/>
  </joint>
  <link name="crate2">
    <visual>
      <origin rpy="0 0 0" xyz="0.0 0.0 0.0"/>
      <geometry>
        <mesh filename="package://mramp/stl/crate.stl" scale="0.01 0.01 0.01"/>
      </geometry>
    </visual>
    <!-- <collision>
      <origin rpy="0 0 0" xyz="0.0 0.0 0.0"/>
      <geometry>
        <mesh filename="package://mramp/stl/crate.stl" scale="0.01 0.01 0.01"/>
      </geometry>
    </collision> -->
  </link>
  <joint name="base_link_to_lamp0_joint" type="fixed">
    <parent link="base"/>
    <child link="lamp0"/>
    <origin rpy="0 0 0" xyz="0.5 0.0 0.8"/>
  </joint>
  <link name="lamp0">
    <visual>
      <origin rpy="0 0 0" xyz="0.0 0.0 0.0"/>
      <geometry>
        <mesh filename="package://mramp/stl/lamp.stl" scale="0.000027 0.000027 0.000027"/>
      </geometry>
    </visual>
    <!-- <collision>
      <origin rpy="0 0 0" xyz="0.0 0.0 0.0"/>
      <geometry>
        <mesh filename="package://mramp/stl/crate.stl" scale="0.01 0.01 0.01"/>
      </geometry>
    </collision> -->
  </link>
  <joint name="base_link_to_lamp1_joint" type="fixed">
    <parent link="base"/>
    <child link="lamp1"/>
    <origin rpy="0 0 0" xyz="0.0 0.0 1.13"/>
  </joint>
  <link name="lamp1">
    <visual>
      <origin rpy="0 0 0" xyz="0.0 0.0 0.0"/>
      <geometry>
        <mesh filename="package://mramp/stl/lamp.stl" scale="0.000027 0.000032 0.000032"/>
      </geometry>
    </visual>
    <!-- <collision>
      <origin rpy="0 0 0" xyz="0.0 0.0 0.0"/>
      <geometry>
        <mesh filename="package://mramp/stl/crate.stl" scale="0.01 0.01 0.01"/>
      </geometry>
    </collision> -->
  </link>
  <joint name="base_link_to_lamp2_joint" type="fixed">
    <parent link="base"/>
    <child link="lamp2"/>
    <origin rpy="0 0 0" xyz="-0.5 0.0 0.8"/>
  </joint>
  <link name="lamp2">
    <visual>
      <origin rpy="0 0 0" xyz="0.0 0.0 0.0"/>
      <geometry>
        <mesh filename="package://mramp/stl/lamp.stl" scale="0.000027 0.000027 0.000027"/>
      </geometry>
    </visual>
    <!-- <collision>
      <origin rpy="0 0 0" xyz="0.0 0.0 0.0"/>
      <geometry>
        <mesh filename="package://mramp/stl/crate.stl" scale="0.01 0.01 0.01"/>
      </geometry>
    </collision> -->
  </link>
  <joint name="panda0_joint_base" type="fixed">
    <parent link="base"/>
    <child link="panda0_link0"/>
    <origin rpy="0 0 2.28" xyz="0.4 -0.4 0.1"/>
  </joint>
  <link name="panda0_link0">
    <visual>
      <geometry>
        <mesh filename="package://moveit_resources_panda_description/meshes/visual/link0.dae"/>
      </geometry>
    </visual>
    <collision>
      <geometry>
        <mesh filename="package://moveit_resources_panda_description/meshes/collision/link0.stl"/>
      </geometry>
    </collision>
  </link>
  <link name="panda0_link1">
    <visual>
      <geometry>
        <mesh filename="package://moveit_resources_panda_description/meshes/visual/link1.dae"/>
      </geometry>
    </visual>
    <collision>
      <geometry>
        <mesh filename="package://moveit_resources_panda_description/meshes/collision/link1.stl"/>
      </geometry>
    </collision>
  </link>
  <joint name="panda0_joint1" type="revolute">
    <safety_controller k_position="100.0" k_velocity="40.0" soft_lower_limit="-2.8973" soft_upper_limit="2.8973"/>
    <origin rpy="0 0 0" xyz="0 0 0.333"/>
    <parent link="panda0_link0"/>
    <child link="panda0_link1"/>
    <axis xyz="0 0 1"/>
    <limit effort="87" lower="-2.9671" upper="2.9671" velocity="2.3925"/>
  </joint>
  <link name="panda0_link2">
    <visual>
      <geometry>
        <mesh filename="package://moveit_resources_panda_description/meshes/visual/link2.dae"/>
      </geometry>
    </visual>
    <collision>
      <geometry>
        <mesh filename="package://moveit_resources_panda_description/meshes/collision/link2.stl"/>
      </geometry>
    </collision>
  </link>
  <joint name="panda0_joint2" type="revolute">
    <safety_controller k_position="100.0" k_velocity="40.0" soft_lower_limit="-1.7628" soft_upper_limit="1.7628"/>
    <origin rpy="-1.5707963267948966 0 0" xyz="0 0 0"/>
    <parent link="panda0_link1"/>
    <child link="panda0_link2"/>
    <axis xyz="0 0 1"/>
    <limit effort="87" lower="-1.8326" upper="1.8326" velocity="2.3925"/>
  </joint>
  <link name="panda0_link3">
    <visual>
      <geometry>
        <mesh filename="package://moveit_resources_panda_description/meshes/visual/link3.dae"/>
      </geometry>
    </visual>
    <collision>
      <geometry>
        <mesh filename="package://moveit_resources_panda_description/meshes/collision/link3.stl"/>
      </geometry>
    </collision>
  </link>
  <joint name="panda0_joint3" type="revolute">
    <safety_controller k_position="100.0" k_velocity="40.0" soft_lower_limit="-2.8973" soft_upper_limit="2.8973"/>
    <origin rpy="1.5707963267948966 0 0" xyz="0 -0.316 0"/>
    <parent link="panda0_link2"/>
    <child link="panda0_link3"/>
    <axis xyz="0 0 1"/>
    <limit effort="87" lower="-2.9671" upper="2.9671" velocity="2.3925"/>
  </joint>
  <link name="panda0_link4">
    <visual>
      <geometry>
        <mesh filename="package://moveit_resources_panda_description/meshes/visual/link4.dae"/>
      </geometry>
    </visual>
    <collision>
      <geometry>
        <mesh filename="package://moveit_resources_panda_description/meshes/collision/link4.stl"/>
      </geometry>
    </collision>
  </link>
  <joint name="panda0_joint4" type="revolute">
    <safety_controller k_position="100.0" k_velocity="40.0" soft_lower_limit="-3.0718" soft_upper_limit="0.0175"/>
    <origin rpy="1.5707963267948966 0 0" xyz="0.0825 0 0"/>
    <parent link="panda0_link3"/>
    <child link="panda0_link4"/>
    <axis xyz="0 0 1"/>
    <limit effort="87" lower="-3.1416" upper="0.0873" velocity="2.3925"/>
  </joint>
  <link name="panda0_link5">
    <visual>
      <geometry>
        <mesh filename="package://moveit_resources_panda_description/meshes/visual/link5.dae"/>
      </geometry>
    </visual>
    <collision>
      <geometry>
        <mesh filename="package://moveit_resources_panda_description/meshes/collision/link5.stl"/>
      </geometry>
    </collision>
  </link>
  <joint name="panda0_joint5" type="revolute">
    <safety_controller k_position="100.0" k_velocity="40.0" soft_lower_limit="-2.8973" soft_upper_limit="2.8973"/>
    <origin rpy="-1.5707963267948966 0 0" xyz="-0.0825 0.384 0"/>
    <parent link="panda0_link4"/>
    <child link="panda0_link5"/>
    <axis xyz="0 0 1"/>
    <limit effort="12" lower="-2.9671" upper="2.9671" velocity="2.8710"/>
  </joint>
  <link name="panda0_link6">
    <visual>
      <geometry>
        <mesh filename="package://moveit_resources_panda_description/meshes/visual/link6.dae"/>
      </geometry>
    </visual>
    <collision>
      <geometry>
        <mesh filename="package://moveit_resources_panda_description/meshes/collision/link6.stl"/>
      </geometry>
    </collision>
  </link>
  <joint name="panda0_joint6" type="revolute">
    <safety_controller k_position="100.0" k_velocity="40.0" soft_lower_limit="-0.0175" soft_upper_limit="3.7525"/>
    <origin rpy="1.5707963267948966 0 0" xyz="0 0 0"/>
    <parent link="panda0_link5"/>
    <child link="panda0_link6"/>
    <axis xyz="0 0 1"/>
    <limit effort="12" lower="-0.0873" upper="3.8223" velocity="2.8710"/>
  </joint>
  <link name="panda0_link7">
    <visual>
      <geometry>
        <mesh filename="package://moveit_resources_panda_description/meshes/visual/link7.dae"/>
      </geometry>
    </visual>
    <collision>
      <geometry>
        <mesh filename="package://moveit_resources_panda_description/meshes/collision/link7.stl"/>
      </geometry>
    </collision>
  </link>
  <joint name="panda0_joint7" type="revolute">
    <safety_controller k_position="100.0" k_velocity="40.0" soft_lower_limit="-2.8973" soft_upper_limit="2.8973"/>
    <origin rpy="1.5707963267948966 0 0" xyz="0.088 0 0"/>
    <parent link="panda0_link6"/>
    <child link="panda0_link7"/>
    <axis xyz="0 0 1"/>
    <limit effort="12" lower="-2.9671" upper="2.9671" velocity="2.8710"/>
  </joint>
  <link name="panda0_link8"/>
  <joint name="panda0_joint8" type="fixed">
    <origin rpy="0 0 0" xyz="0 0 0.107"/>
    <parent link="panda0_link7"/>
    <child link="panda0_link8"/>
    <axis xyz="0 0 0"/>
  </joint>
  <joint name="panda0_hand_joint" type="fixed">
    <parent link="panda0_link8"/>
    <child link="panda0_hand"/>
    <origin rpy="0 0 0" xyz="0 0 0"/>
  </joint>
  <link name="panda0_hand">
    <visual>
      <geometry>
        <mesh filename="package://moveit_resources_panda_description/meshes/visual/hand.dae"/>
      </geometry>
    </visual>
    <collision>
      <geometry>
        <mesh filename="package://moveit_resources_panda_description/meshes/collision/hand.stl"/>
      </geometry>
    </collision>
  </link>
  <link name="panda0_leftfinger">
    <visual>
      <geometry>
        <mesh filename="package://moveit_resources_panda_description/meshes/visual/finger.dae"/>
      </geometry>
    </visual>
    <collision>
      <geometry>
        <mesh filename="package://moveit_resources_panda_description/meshes/collision/finger.stl"/>
      </geometry>
    </collision>
  </link>
  <link name="panda0_rightfinger">
    <visual>
      <origin rpy="0 0 3.141592653589793" xyz="0 0 0"/>
      <geometry>
        <mesh filename="package://moveit_resources_panda_description/meshes/visual/finger.dae"/>
      </geometry>
    </visual>
    <collision>
      <origin rpy="0 0 3.141592653589793" xyz="0 0 0"/>
      <geometry>
        <mesh filename="package://moveit_resources_panda_description/meshes/collision/finger.stl"/>
      </geometry>
    </collision>
  </link>
  <joint name="panda0_finger_joint1" type="prismatic">
    <parent link="panda0_hand"/>
    <child link="panda0_leftfinger"/>
    <origin rpy="0 0 0" xyz="0 0 0.0584"/>
    <axis xyz="0 1 0"/>
    <limit effort="20" lower="0.0" upper="0.04" velocity="0.2"/>
  </joint>
  <joint name="panda0_finger_joint2" type="prismatic">
    <parent link="panda0_hand"/>
    <child link="panda0_rightfinger"/>
    <origin rpy="0 0 0" xyz="0 0 0.0584"/>
    <axis xyz="0 -1 0"/>
    <limit effort="20" lower="0.0" upper="0.04" velocity="0.2"/>
    <mimic joint="panda0_finger_joint1"/>
  </joint>
  <joint name="panda1_joint_base" type="fixed">
    <parent link="base"/>
    <child link="panda1_link0"/>
    <origin rpy="0 0 0.66" xyz="-0.4 -0.4 0.1"/>
  </joint>
  <link name="panda1_link0">
    <visual>
      <geometry>
        <mesh filename="package://moveit_resources_panda_description/meshes/visual/link0.dae"/>
      </geometry>
    </visual>
    <collision>
      <geometry>
        <mesh filename="package://moveit_resources_panda_description/meshes/collision/link0.stl"/>
      </geometry>
    </collision>
  </link>
  <link name="panda1_link1">
    <visual>
      <geometry>
        <mesh filename="package://moveit_resources_panda_description/meshes/visual/link1.dae"/>
      </geometry>
    </visual>
    <collision>
      <geometry>
        <mesh filename="package://moveit_resources_panda_description/meshes/collision/link1.stl"/>
      </geometry>
    </collision>
  </link>
  <joint name="panda1_joint1" type="revolute">
    <safety_controller k_position="100.0" k_velocity="40.0" soft_lower_limit="-2.8973" soft_upper_limit="2.8973"/>
    <origin rpy="0 0 0" xyz="0 0 0.333"/>
    <parent link="panda1_link0"/>
    <child link="panda1_link1"/>
    <axis xyz="0 0 1"/>
    <limit effort="87" lower="-2.9671" upper="2.9671" velocity="2.3925"/>
  </joint>
  <link name="panda1_link2">
    <visual>
      <geometry>
        <mesh filename="package://moveit_resources_panda_description/meshes/visual/link2.dae"/>
      </geometry>
    </visual>
    <collision>
      <geometry>
        <mesh filename="package://moveit_resources_panda_description/meshes/collision/link2.stl"/>
      </geometry>
    </collision>
  </link>
  <joint name="panda1_joint2" type="revolute">
    <safety_controller k_position="100.0" k_velocity="40.0" soft_lower_limit="-1.7628" soft_upper_limit="1.7628"/>
    <origin rpy="-1.5707963267948966 0 0" xyz="0 0 0"/>
    <parent link="panda1_link1"/>
    <child link="panda1_link2"/>
    <axis xyz="0 0 1"/>
    <limit effort="87" lower="-1.8326" upper="1.8326" velocity="2.3925"/>
  </joint>
  <link name="panda1_link3">
    <visual>
      <geometry>
        <mesh filename="package://moveit_resources_panda_description/meshes/visual/link3.dae"/>
      </geometry>
    </visual>
    <collision>
      <geometry>
        <mesh filename="package://moveit_resources_panda_description/meshes/collision/link3.stl"/>
      </geometry>
    </collision>
  </link>
  <joint name="panda1_joint3" type="revolute">
    <safety_controller k_position="100.0" k_velocity="40.0" soft_lower_limit="-2.8973" soft_upper_limit="2.8973"/>
    <origin rpy="1.5707963267948966 0 0" xyz="0 -0.316 0"/>
    <parent link="panda1_link2"/>
    <child link="panda1_link3"/>
    <axis xyz="0 0 1"/>
    <limit effort="87" lower="-2.9671" upper="2.9671" velocity="2.3925"/>
  </joint>
  <link name="panda1_link4">
    <visual>
      <geometry>
        <mesh filename="package://moveit_resources_panda_description/meshes/visual/link4.dae"/>
      </geometry>
    </visual>
    <collision>
      <geometry>
        <mesh filename="package://moveit_resources_panda_description/meshes/collision/link4.stl"/>
      </geometry>
    </collision>
  </link>
  <joint name="panda1_joint4" type="revolute">
    <safety_controller k_position="100.0" k_velocity="40.0" soft_lower_limit="-3.0718" soft_upper_limit="0.0175"/>
    <origin rpy="1.5707963267948966 0 0" xyz="0.0825 0 0"/>
    <parent link="panda1_link3"/>
    <child link="panda1_link4"/>
    <axis xyz="0 0 1"/>
    <limit effort="87" lower="-3.1416" upper="0.0873" velocity="2.3925"/>
  </joint>
  <link name="panda1_link5">
    <visual>
      <geometry>
        <mesh filename="package://moveit_resources_panda_description/meshes/visual/link5.dae"/>
      </geometry>
    </visual>
    <collision>
      <geometry>
        <mesh filename="package://moveit_resources_panda_description/meshes/collision/link5.stl"/>
      </geometry>
    </collision>
  </link>
  <joint name="panda1_joint5" type="revolute">
    <safety_controller k_position="100.0" k_velocity="40.0" soft_lower_limit="-2.8973" soft_upper_limit="2.8973"/>
    <origin rpy="-1.5707963267948966 0 0" xyz="-0.0825 0.384 0"/>
    <parent link="panda1_link4"/>
    <child link="panda1_link5"/>
    <axis xyz="0 0 1"/>
    <limit effort="12" lower="-2.9671" upper="2.9671" velocity="2.8710"/>
  </joint>
  <link name="panda1_link6">
    <visual>
      <geometry>
        <mesh filename="package://moveit_resources_panda_description/meshes/visual/link6.dae"/>
      </geometry>
    </visual>
    <collision>
      <geometry>
        <mesh filename="package://moveit_resources_panda_description/meshes/collision/link6.stl"/>
      </geometry>
    </collision>
  </link>
  <joint name="panda1_joint6" type="revolute">
    <safety_controller k_position="100.0" k_velocity="40.0" soft_lower_limit="-0.0175" soft_upper_limit="3.7525"/>
    <origin rpy="1.5707963267948966 0 0" xyz="0 0 0"/>
    <parent link="panda1_link5"/>
    <child link="panda1_link6"/>
    <axis xyz="0 0 1"/>
    <limit effort="12" lower="-0.0873" upper="3.8223" velocity="2.8710"/>
  </joint>
  <link name="panda1_link7">
    <visual>
      <geometry>
        <mesh filename="package://moveit_resources_panda_description/meshes/visual/link7.dae"/>
      </geometry>
    </visual>
    <collision>
      <geometry>
        <mesh filename="package://moveit_resources_panda_description/meshes/collision/link7.stl"/>
      </geometry>
    </collision>
  </link>
  <joint name="panda1_joint7" type="revolute">
    <safety_controller k_position="100.0" k_velocity="40.0" soft_lower_limit="-2.8973" soft_upper_limit="2.8973"/>
    <origin rpy="1.5707963267948966 0 0" xyz="0.088 0 0"/>
    <parent link="panda1_link6"/>
    <child link="panda1_link7"/>
    <axis xyz="0 0 1"/>
    <limit effort="12" lower="-2.9671" upper="2.9671" velocity="2.8710"/>
  </joint>
  <link name="panda1_link8"/>
  <joint name="panda1_joint8" type="fixed">
    <origin rpy="0 0 0" xyz="0 0 0.107"/>
    <parent link="panda1_link7"/>
    <child link="panda1_link8"/>
    <axis xyz="0 0 0"/>
  </joint>
  <joint name="panda1_hand_joint" type="fixed">
    <parent link="panda1_link8"/>
    <child link="panda1_hand"/>
    <origin rpy="0 0 0" xyz="0 0 0"/>
  </joint>
  <link name="panda1_hand">
    <visual>
      <geometry>
        <mesh filename="package://moveit_resources_panda_description/meshes/visual/hand.dae"/>
      </geometry>
    </visual>
    <collision>
      <geometry>
        <mesh filename="package://moveit_resources_panda_description/meshes/collision/hand.stl"/>
      </geometry>
    </collision>
  </link>
  <link name="panda1_leftfinger">
    <visual>
      <geometry>
        <mesh filename="package://moveit_resources_panda_description/meshes/visual/finger.dae"/>
      </geometry>
    </visual>
    <collision>
      <geometry>
        <mesh filename="package://moveit_resources_panda_description/meshes/collision/finger.stl"/>
      </geometry>
    </collision>
  </link>
  <link name="panda1_rightfinger">
    <visual>
      <origin rpy="0 0 3.141592653589793" xyz="0 0 0"/>
      <geometry>
        <mesh filename="package://moveit_resources_panda_description/meshes/visual/finger.dae"/>
      </geometry>
    </visual>
    <collision>
      <origin rpy="0 0 3.141592653589793" xyz="0 0 0"/>
      <geometry>
        <mesh filename="package://moveit_resources_panda_description/meshes/collision/finger.stl"/>
      </geometry>
    </collision>
  </link>
  <joint name="panda1_finger_joint1" type="prismatic">
    <parent link="panda1_hand"/>
    <child link="panda1_leftfinger"/>
    <origin rpy="0 0 0" xyz="0 0 0.0584"/>
    <axis xyz="0 1 0"/>
    <limit effort="20" lower="0.0" upper="0.04" velocity="0.2"/>
  </joint>
  <joint name="panda1_finger_joint2" type="prismatic">
    <parent link="panda1_hand"/>
    <child link="panda1_rightfinger"/>
    <origin rpy="0 0 0" xyz="0 0 0.0584"/>
    <axis xyz="0 -1 0"/>
    <limit effort="20" lower="0.0" upper="0.04" velocity="0.2"/>
    <mimic joint="panda1_finger_joint1"/>
  </joint>
  <joint name="panda2_joint_base" type="fixed">
    <parent link="base"/>
    <child link="panda2_link0"/>
    <origin rpy="0 0 -0.66" xyz="-0.4 0.4 0.1"/>
  </joint>
  <link name="panda2_link0">
    <visual>
      <geometry>
        <mesh filename="package://moveit_resources_panda_description/meshes/visual/link0.dae"/>
      </geometry>
    </visual>
    <collision>
      <geometry>
        <mesh filename="package://moveit_resources_panda_description/meshes/collision/link0.stl"/>
      </geometry>
    </collision>
  </link>
  <link name="panda2_link1">
    <visual>
      <geometry>
        <mesh filename="package://moveit_resources_panda_description/meshes/visual/link1.dae"/>
      </geometry>
    </visual>
    <collision>
      <geometry>
        <mesh filename="package://moveit_resources_panda_description/meshes/collision/link1.stl"/>
      </geometry>
    </collision>
  </link>
  <joint name="panda2_joint1" type="revolute">
    <safety_controller k_position="100.0" k_velocity="40.0" soft_lower_limit="-2.8973" soft_upper_limit="2.8973"/>
    <origin rpy="0 0 0" xyz="0 0 0.333"/>
    <parent link="panda2_link0"/>
    <child link="panda2_link1"/>
    <axis xyz="0 0 1"/>
    <limit effort="87" lower="-2.9671" upper="2.9671" velocity="2.3925"/>
  </joint>
  <link name="panda2_link2">
    <visual>
      <geometry>
        <mesh filename="package://moveit_resources_panda_description/meshes/visual/link2.dae"/>
      </geometry>
    </visual>
    <collision>
      <geometry>
        <mesh filename="package://moveit_resources_panda_description/meshes/collision/link2.stl"/>
      </geometry>
    </collision>
  </link>
  <joint name="panda2_joint2" type="revolute">
    <safety_controller k_position="100.0" k_velocity="40.0" soft_lower_limit="-1.7628" soft_upper_limit="1.7628"/>
    <origin rpy="-1.5707963267948966 0 0" xyz="0 0 0"/>
    <parent link="panda2_link1"/>
    <child link="panda2_link2"/>
    <axis xyz="0 0 1"/>
    <limit effort="87" lower="-1.8326" upper="1.8326" velocity="2.3925"/>
  </joint>
  <link name="panda2_link3">
    <visual>
      <geometry>
        <mesh filename="package://moveit_resources_panda_description/meshes/visual/link3.dae"/>
      </geometry>
    </visual>
    <collision>
      <geometry>
        <mesh filename="package://moveit_resources_panda_description/meshes/collision/link3.stl"/>
      </geometry>
    </collision>
  </link>
  <joint name="panda2_joint3" type="revolute">
    <safety_controller k_position="100.0" k_velocity="40.0" soft_lower_limit="-2.8973" soft_upper_limit="2.8973"/>
    <origin rpy="1.5707963267948966 0 0" xyz="0 -0.316 0"/>
    <parent link="panda2_link2"/>
    <child link="panda2_link3"/>
    <axis xyz="0 0 1"/>
    <limit effort="87" lower="-2.9671" upper="2.9671" velocity="2.3925"/>
  </joint>
  <link name="panda2_link4">
    <visual>
      <geometry>
        <mesh filename="package://moveit_resources_panda_description/meshes/visual/link4.dae"/>
      </geometry>
    </visual>
    <collision>
      <geometry>
        <mesh filename="package://moveit_resources_panda_description/meshes/collision/link4.stl"/>
      </geometry>
    </collision>
  </link>
  <joint name="panda2_joint4" type="revolute">
    <safety_controller k_position="100.0" k_velocity="40.0" soft_lower_limit="-3.0718" soft_upper_limit="0.0175"/>
    <origin rpy="1.5707963267948966 0 0" xyz="0.0825 0 0"/>
    <parent link="panda2_link3"/>
    <child link="panda2_link4"/>
    <axis xyz="0 0 1"/>
    <limit effort="87" lower="-3.1416" upper="0.0873" velocity="2.3925"/>
  </joint>
  <link name="panda2_link5">
    <visual>
      <geometry>
        <mesh filename="package://moveit_resources_panda_description/meshes/visual/link5.dae"/>
      </geometry>
    </visual>
    <collision>
      <geometry>
        <mesh filename="package://moveit_resources_panda_description/meshes/collision/link5.stl"/>
      </geometry>
    </collision>
  </link>
  <joint name="panda2_joint5" type="revolute">
    <safety_controller k_position="100.0" k_velocity="40.0" soft_lower_limit="-2.8973" soft_upper_limit="2.8973"/>
    <origin rpy="-1.5707963267948966 0 0" xyz="-0.0825 0.384 0"/>
    <parent link="panda2_link4"/>
    <child link="panda2_link5"/>
    <axis xyz="0 0 1"/>
    <limit effort="12" lower="-2.9671" upper="2.9671" velocity="2.8710"/>
  </joint>
  <link name="panda2_link6">
    <visual>
      <geometry>
        <mesh filename="package://moveit_resources_panda_description/meshes/visual/link6.dae"/>
      </geometry>
    </visual>
    <collision>
      <geometry>
        <mesh filename="package://moveit_resources_panda_description/meshes/collision/link6.stl"/>
      </geometry>
    </collision>
  </link>
  <joint name="panda2_joint6" type="revolute">
    <safety_controller k_position="100.0" k_velocity="40.0" soft_lower_limit="-0.0175" soft_upper_limit="3.7525"/>
    <origin rpy="1.5707963267948966 0 0" xyz="0 0 0"/>
    <parent link="panda2_link5"/>
    <child link="panda2_link6"/>
    <axis xyz="0 0 1"/>
    <limit effort="12" lower="-0.0873" upper="3.8223" velocity="2.8710"/>
  </joint>
  <link name="panda2_link7">
    <visual>
      <geometry>
        <mesh filename="package://moveit_resources_panda_description/meshes/visual/link7.dae"/>
      </geometry>
    </visual>
    <collision>
      <geometry>
        <mesh filename="package://moveit_resources_panda_description/meshes/collision/link7.stl"/>
      </geometry>
    </collision>
  </link>
  <joint name="panda2_joint7" type="revolute">
    <safety_controller k_position="100.0" k_velocity="40.0" soft_lower_limit="-2.8973" soft_upper_limit="2.8973"/>
    <origin rpy="1.5707963267948966 0 0" xyz="0.088 0 0"/>
    <parent link="panda2_link6"/>
    <child link="panda2_link7"/>
    <axis xyz="0 0 1"/>
    <limit effort="12" lower="-2.9671" upper="2.9671" velocity="2.8710"/>
  </joint>
  <link name="panda2_link8"/>
  <joint name="panda2_joint8" type="fixed">
    <origin rpy="0 0 0" xyz="0 0 0.107"/>
    <parent link="panda2_link7"/>
    <child link="panda2_link8"/>
    <axis xyz="0 0 0"/>
  </joint>
  <joint name="panda2_hand_joint" type="fixed">
    <parent link="panda2_link8"/>
    <child link="panda2_hand"/>
    <origin rpy="0 0 0" xyz="0 0 0"/>
  </joint>
  <link name="panda2_hand">
    <visual>
      <geometry>
        <mesh filename="package://moveit_resources_panda_description/meshes/visual/hand.dae"/>
      </geometry>
    </visual>
    <collision>
      <geometry>
        <mesh filename="package://moveit_resources_panda_description/meshes/collision/hand.stl"/>
      </geometry>
    </collision>
  </link>
  <link name="panda2_leftfinger">
    <visual>
      <geometry>
        <mesh filename="package://moveit_resources_panda_description/meshes/visual/finger.dae"/>
      </geometry>
    </visual>
    <collision>
      <geometry>
        <mesh filename="package://moveit_resources_panda_description/meshes/collision/finger.stl"/>
      </geometry>
    </collision>
  </link>
  <link name="panda2_rightfinger">
    <visual>
      <origin rpy="0 0 3.141592653589793" xyz="0 0 0"/>
      <geometry>
        <mesh filename="package://moveit_resources_panda_description/meshes/visual/finger.dae"/>
      </geometry>
    </visual>
    <collision>
      <origin rpy="0 0 3.141592653589793" xyz="0 0 0"/>
      <geometry>
        <mesh filename="package://moveit_resources_panda_description/meshes/collision/finger.stl"/>
      </geometry>
    </collision>
  </link>
  <joint name="panda2_finger_joint1" type="prismatic">
    <parent link="panda2_hand"/>
    <child link="panda2_leftfinger"/>
    <origin rpy="0 0 0" xyz="0 0 0.0584"/>
    <axis xyz="0 1 0"/>
    <limit effort="20" lower="0.0" upper="0.04" velocity="0.2"/>
  </joint>
  <joint name="panda2_finger_joint2" type="prismatic">
    <parent link="panda2_hand"/>
    <child link="panda2_rightfinger"/>
    <origin rpy="0 0 0" xyz="0 0 0.0584"/>
    <axis xyz="0 -1 0"/>
    <limit effort="20" lower="0.0" upper="0.04" velocity="0.2"/>
    <mimic joint="panda2_finger_joint1"/>
  </joint>
  <joint name="panda3_joint_base" type="fixed">
    <parent link="base"/>
    <child link="panda3_link0"/>
    <origin rpy="0 0 -2.28" xyz="0.4 0.4 0.1"/>
  </joint>
  <link name="panda3_link0">
    <visual>
      <geometry>
        <mesh filename="package://moveit_resources_panda_description/meshes/visual/link0.dae"/>
      </geometry>
    </visual>
    <collision>
      <geometry>
        <mesh filename="package://moveit_resources_panda_description/meshes/collision/link0.stl"/>
      </geometry>
    </collision>
  </link>
  <link name="panda3_link1">
    <visual>
      <geometry>
        <mesh filename="package://moveit_resources_panda_description/meshes/visual/link1.dae"/>
      </geometry>
    </visual>
    <collision>
      <geometry>
        <mesh filename="package://moveit_resources_panda_description/meshes/collision/link1.stl"/>
      </geometry>
    </collision>
  </link>
  <joint name="panda3_joint1" type="revolute">
    <safety_controller k_position="100.0" k_velocity="40.0" soft_lower_limit="-2.8973" soft_upper_limit="2.8973"/>
    <origin rpy="0 0 0" xyz="0 0 0.333"/>
    <parent link="panda3_link0"/>
    <child link="panda3_link1"/>
    <axis xyz="0 0 1"/>
    <limit effort="87" lower="-2.9671" upper="2.9671" velocity="2.3925"/>
  </joint>
  <link name="panda3_link2">
    <visual>
      <geometry>
        <mesh filename="package://moveit_resources_panda_description/meshes/visual/link2.dae"/>
      </geometry>
    </visual>
    <collision>
      <geometry>
        <mesh filename="package://moveit_resources_panda_description/meshes/collision/link2.stl"/>
      </geometry>
    </collision>
  </link>
  <joint name="panda3_joint2" type="revolute">
    <safety_controller k_position="100.0" k_velocity="40.0" soft_lower_limit="-1.7628" soft_upper_limit="1.7628"/>
    <origin rpy="-1.5707963267948966 0 0" xyz="0 0 0"/>
    <parent link="panda3_link1"/>
    <child link="panda3_link2"/>
    <axis xyz="0 0 1"/>
    <limit effort="87" lower="-1.8326" upper="1.8326" velocity="2.3925"/>
  </joint>
  <link name="panda3_link3">
    <visual>
      <geometry>
        <mesh filename="package://moveit_resources_panda_description/meshes/visual/link3.dae"/>
      </geometry>
    </visual>
    <collision>
      <geometry>
        <mesh filename="package://moveit_resources_panda_description/meshes/collision/link3.stl"/>
      </geometry>
    </collision>
  </link>
  <joint name="panda3_joint3" type="revolute">
    <safety_controller k_position="100.0" k_velocity="40.0" soft_lower_limit="-2.8973" soft_upper_limit="2.8973"/>
    <origin rpy="1.5707963267948966 0 0" xyz="0 -0.316 0"/>
    <parent link="panda3_link2"/>
    <child link="panda3_link3"/>
    <axis xyz="0 0 1"/>
    <limit effort="87" lower="-2.9671" upper="2.9671" velocity="2.3925"/>
  </joint>
  <link name="panda3_link4">
    <visual>
      <geometry>
        <mesh filename="package://moveit_resources_panda_description/meshes/visual/link4.dae"/>
      </geometry>
    </visual>
    <collision>
      <geometry>
        <mesh filename="package://moveit_resources_panda_description/meshes/collision/link4.stl"/>
      </geometry>
    </collision>
  </link>
  <joint name="panda3_joint4" type="revolute">
    <safety_controller k_position="100.0" k_velocity="40.0" soft_lower_limit="-3.0718" soft_upper_limit="0.0175"/>
    <origin rpy="1.5707963267948966 0 0" xyz="0.0825 0 0"/>
    <parent link="panda3_link3"/>
    <child link="panda3_link4"/>
    <axis xyz="0 0 1"/>
    <limit effort="87" lower="-3.1416" upper="0.0873" velocity="2.3925"/>
  </joint>
  <link name="panda3_link5">
    <visual>
      <geometry>
        <mesh filename="package://moveit_resources_panda_description/meshes/visual/link5.dae"/>
      </geometry>
    </visual>
    <collision>
      <geometry>
        <mesh filename="package://moveit_resources_panda_description/meshes/collision/link5.stl"/>
      </geometry>
    </collision>
  </link>
  <joint name="panda3_joint5" type="revolute">
    <safety_controller k_position="100.0" k_velocity="40.0" soft_lower_limit="-2.8973" soft_upper_limit="2.8973"/>
    <origin rpy="-1.5707963267948966 0 0" xyz="-0.0825 0.384 0"/>
    <parent link="panda3_link4"/>
    <child link="panda3_link5"/>
    <axis xyz="0 0 1"/>
    <limit effort="12" lower="-2.9671" upper="2.9671" velocity="2.8710"/>
  </joint>
  <link name="panda3_link6">
    <visual>
      <geometry>
        <mesh filename="package://moveit_resources_panda_description/meshes/visual/link6.dae"/>
      </geometry>
    </visual>
    <collision>
      <geometry>
        <mesh filename="package://moveit_resources_panda_description/meshes/collision/link6.stl"/>
      </geometry>
    </collision>
  </link>
  <joint name="panda3_joint6" type="revolute">
    <safety_controller k_position="100.0" k_velocity="40.0" soft_lower_limit="-0.0175" soft_upper_limit="3.7525"/>
    <origin rpy="1.5707963267948966 0 0" xyz="0 0 0"/>
    <parent link="panda3_link5"/>
    <child link="panda3_link6"/>
    <axis xyz="0 0 1"/>
    <limit effort="12" lower="-0.0873" upper="3.8223" velocity="2.8710"/>
  </joint>
  <link name="panda3_link7">
    <visual>
      <geometry>
        <mesh filename="package://moveit_resources_panda_description/meshes/visual/link7.dae"/>
      </geometry>
    </visual>
    <collision>
      <geometry>
        <mesh filename="package://moveit_resources_panda_description/meshes/collision/link7.stl"/>
      </geometry>
    </collision>
  </link>
  <joint name="panda3_joint7" type="revolute">
    <safety_controller k_position="100.0" k_velocity="40.0" soft_lower_limit="-2.8973" soft_upper_limit="2.8973"/>
    <origin rpy="1.5707963267948966 0 0" xyz="0.088 0 0"/>
    <parent link="panda3_link6"/>
    <child link="panda3_link7"/>
    <axis xyz="0 0 1"/>
    <limit effort="12" lower="-2.9671" upper="2.9671" velocity="2.8710"/>
  </joint>
  <link name="panda3_link8"/>
  <joint name="panda3_joint8" type="fixed">
    <origin rpy="0 0 0" xyz="0 0 0.107"/>
    <parent link="panda3_link7"/>
    <child link="panda3_link8"/>
    <axis xyz="0 0 0"/>
  </joint>
  <joint name="panda3_hand_joint" type="fixed">
    <parent link="panda3_link8"/>
    <child link="panda3_hand"/>
    <origin rpy="0 0 0" xyz="0 0 0"/>
  </joint>
  <link name="panda3_hand">
    <visual>
      <geometry>
        <mesh filename="package://moveit_resources_panda_description/meshes/visual/hand.dae"/>
      </geometry>
    </visual>
    <collision>
      <geometry>
        <mesh filename="package://moveit_resources_panda_description/meshes/collision/hand.stl"/>
      </geometry>
    </collision>
  </link>
  <link name="panda3_leftfinger">
    <visual>
      <geometry>
        <mesh filename="package://moveit_resources_panda_description/meshes/visual/finger.dae"/>
      </geometry>
    </visual>
    <collision>
      <geometry>
        <mesh filename="package://moveit_resources_panda_description/meshes/collision/finger.stl"/>
      </geometry>
    </collision>
  </link>
  <link name="panda3_rightfinger">
    <visual>
      <origin rpy="0 0 3.141592653589793" xyz="0 0 0"/>
      <geometry>
        <mesh filename="package://moveit_resources_panda_description/meshes/visual/finger.dae"/>
      </geometry>
    </visual>
    <collision>
      <origin rpy="0 0 3.141592653589793" xyz="0 0 0"/>
      <geometry>
        <mesh filename="package://moveit_resources_panda_description/meshes/collision/finger.stl"/>
      </geometry>
    </collision>
  </link>
  <joint name="panda3_finger_joint1" type="prismatic">
    <parent link="panda3_hand"/>
    <child link="panda3_leftfinger"/>
    <origin rpy="0 0 0" xyz="0 0 0.0584"/>
    <axis xyz="0 1 0"/>
    <limit effort="20" lower="0.0" upper="0.04" velocity="0.2"/>
  </joint>
  <joint name="panda3_finger_joint2" type="prismatic">
    <parent link="panda3_hand"/>
    <child link="panda3_rightfinger"/>
    <origin rpy="0 0 0" xyz="0 0 0.0584"/>
    <axis xyz="0 -1 0"/>
    <limit effort="20" lower="0.0" upper="0.04" velocity="0.2"/>
    <mimic joint="panda3_finger_joint1"/>
  </joint>
</robot>

